:func:`asyncio.Condition.wait()` now re-raises the same :exc:`CancelledError` instance that may have caused it to be interrupted.  Fixed race condition in :func:`asyncio.Semaphore.aquire` when interrupted with a :exc:`CancelledError`.
